Workbook

Sheet Dane
A1: Tu należy zamieścić analizowane dane.
A2: https://www.kaggle.com/datasets/nejilee/indian-economy-from-1960-to-2020
A3: India - Patent applications
A4: y gdp lg | B4: X1Patent applications, nonresidents | C4: X2Population ages 05-09, female (% of female population) | D4: X3Survival to age 65 male | E4: X4domestic companies, t | F4: X5Imports of goods and services (% of GDP)=x2 | G4: X6Exports of goods and services (% of GDP) | H4: X7 Total reserves (includes gold, current US$) | I4: X8 x%Inflation, consumer prices (annual %) | J4: X9Population, total | K4: X10Population growth (annual %) | L4: X11Life expectancy at birth, total (years)
A5: 26.108963 | B5: 1.948 | C5: 39.02 | D5: 52.1 | E5: 1.151 | F5: 7.85 | G5: 5.84 | H5: 8.2157324e+09 | I5: 11.87 | J5: 745826546 | K5: 2.28 | L5: 54.91 | M5: 1983
A6: 26.080598 | B6: 2.291 | C6: 38.91 | D6: 52.6 | E6: 1.295 | F6: 7.73 | G6: 6.28 | H6: 8.5359445e+09 | I6: 8.32 | J6: 762895156 | K6: 2.29 | L6: 55.27 | M6: 1984
A7: 26.172207 | B7: 2.493 | C7: 38.75 | D7: 53.11 | E7: 1.529 | F7: 7.65 | G7: 5.25 | H7: 9.493103e+09 | I7: 5.56 | J7: 780242084 | K7: 2.27 | L7: 55.62 | M7: 1985
A8: 26.240662 | B8: 2.497 | C8: 38.71 | D8: 53.62 | E8: 1.911 | F8: 7.02 | G8: 5.2 | H8: 1.0480103e+10 | I8: 8.73 | J8: 797878993 | K8: 2.26 | L8: 55.98 | M8: 1986
A9: 26.354598 | B9: 2.52 | C9: 38.58 | D9: 54.12 | E9: 2.095 | F9: 6.98 | G9: 5.6 | H9: 1.1511741e+10 | I9: 8.8 | J9: 815716125 | K9: 2.24 | L9: 56.33 | M9: 1987
A10: 26.415613 | B10: 2.504 | C10: 38.4 | D10: 55.02 | E10: 2.24 | F10: 7.46 | G10: 6.04 | H10: 9.1858394e+09 | I10: 9.38 | J10: 833729681 | K10: 2.21 | L10: 56.69 | M10: 1988
A11: 26.413768 | B11: 2.6 | C11: 38.19 | D11: 55.91 | E11: 2.407 | F11: 8.15 | G11: 7.02 | H11: 8.0484559e+09 | I11: 7.07 | J11: 852012673 | K11: 2.19 | L11: 57.18 | M11: 1989
A12: 26.494642 | B12: 2.673 | C12: 37.97 | D12: 56.8 | E12: 2.435 | F12: 8.45 | G12: 7.05 | H12: 5.6374464e+09 | I12: 8.97 | J12: 870452165 | K12: 2.16 | L12: 57.66 | M12: 1990
A13: 26.322078 | B13: 2.328 | C13: 37.77 | D13: 57.7 | E13: 2.556 | F13: 8.49 | G13: 8.49 | H13: 7.6159875e+09 | I13: 13.87 | J13: 888941756 | K13: 2.12 | L13: 58.15 | M13: 1991
A14: 26.38695 | B14: 2.176 | C14: 37.54 | D14: 58.59 | E14: 2.781 | F14: 9.59 | G14: 8.84 | H14: 9.538786e+09 | I14: 11.79 | J14: 907574049 | K14: 2.1 | L14: 58.63 | M14: 1992
A15: 26.355538 | B15: 2.511 | C15: 37.29 | D15: 59.44 | E15: 3.263 | F15: 9.82 | G15: 9.83 | H15: 1.4674627e+10 | I15: 6.33 | J15: 926351297 | K15: 2.07 | L15: 59.12 | M15: 1993
A16: 26.514068 | B16: 3.212 | C16: 36.99 | D16: 60.3 | E16: 4.413 | F16: 10.19 | G16: 9.89 | H16: 2.4220928e+10 | I16: 10.25 | J16: 945261958 | K16: 2.04 | L16: 59.59 | M16: 1994
... A42: 28.612233 | B42: 33.63 | C42: 26.16 | D42: 75.37 | E42: 5.215 | F42: 19.1 | G42: 18.71 | H42: 5.9022736e+11 | I42: 6.62 | J42: 1396387127 | K42: 0.96 | L42: 69.73 | M42: 2020

Sheet 1. Opis danych
A1: Proszę krótko scharakteryzować dane: (przedstawić źródło danych, podać jednostki, w jakich wyrażane są poszczególne zmienne), zaprezentować wykresy X-Y zależności zmiennej objaśnianej od poszczególnych potencjalnych zmiennych objaśniających).
B5: Y | C5: Zlogarytmowane naturalnie w dolarach Amerykańskich
B6: X1 | C6: liczba zgłoszeń patentowychn w tyś sztuk
B7: X2 | C7: % damskiej populacji
B8: X3 | C8: % meskiej populacji
B9: X4 | C9: tysiącach sztuk
B10: X5 | C10: % GDP
B11: X6 | C11: % GDP
B12: X7 | C12: US$
B13: X8 | C13: %
B14: X9 | C14: w szt
B15: X10 | C15: %
B16: X11 | C16: lata
B23: Y | C23: Pkb | D23: Zlogarytmowane naturalnie w dolarach Amerykańskich
B24: X1 | C24: liczba zgoszen patentowych | D24: w tyś sztuk
B25: X2 | C25: Damska populacja | D25: %
B26: X3 | C26: Męska populacja | D26: %
B27: X4 | C27: Krajowe firmy | D27: tysiącach sztuk
B28: X5 | C28: import | D28: % GDP
B29: X6 | C29: export | D29: % GDP
B30: X7 | C30: Rezerwy krajowe | D30: US$
B31: X8 | C31: Inflacja | D31: %
B32: X9 | C32: Populacja | D32: w szt
B33: X10 | C33: Wzrost populacji | D33: %
B34: X11 | C34: Oczekiwana dlugosc zycia | D34: lata

Sheet 2. Dobór zmiennych
A1: Na początku proszę sprawdzić czy występują zmienne quasi-stałe.
A4: Potem należy zastosować jedną z metod doboru zmiennych objaśniających, np.:
A5: metodę analizy współczynników korelacji
A6: metodę Hellwiga
A7: metody regresji krokowej
B10: Quasi-stałe
C11: V1 | D11: V2 | E11: V3 | F11: V4 | G11: V5 | H11: V6 | I11: V7 | J11: V8 | K11: V9 | L11: V10 | M11: V11
C12: =_xlfn.STDEV.S(Dane!B5:B42)/AVERAGE(Dane!B5:B42) -> 0.85604151 | D12: =_xlfn.STDEV.S(Dane!C5:C42)/AVERAGE(Dane!C5:C42) -> 0.12094001 | E12: =_xlfn.STDEV.S(Dane!D5:D42)/AVERAGE(Dane!D5:D42) -> 0.11348523 | F12: =_xlfn.STDEV.S(Dane!E5:E42)/AVERAGE(Dane!E5:E42) -> 0.35014656 | G12: =_xlfn.STDEV.S(Dane!F5:F42)/AVERAGE(Dane!F5:F42) -> 0.46822242 | H12: =_xlfn.STDEV.S(Dane!G5:G42)/AVERAGE(Dane!G5:G42) -> 0.45124683 | I12: =_xlfn.STDEV.S(Dane!H5:H42)/AVERAGE(Dane!H5:H42) -> 1.0646918 | J12: =_xlfn.STDEV.S(Dane!I5:I42)/AVERAGE(Dane!I5:I42) -> 0.39996576 | ... M12: =_xlfn.STDEV.S(Dane!L5:L42)/AVERAGE(Dane!L5:L42) -> 0.074502661
B14: V*= | C14: 0.1
B16: H0: zmienna jest quasi-stała
B17: H1: zmienna nie jest quasi-stała
B18: Odp: Odrzucamy x11, ponieważ V11 jest mniejsze od V*, stąd wiemy, że zmienna x11 jest quasi-stała. Przyjmujemy H0. Dla zmiennych, x1,x2,x3,x4,x5,x6,x7,x8,x9,10 odrzucamy H0 na rzecz hipotezy h1, stąd wiemy że te zmienne nie są quasi-stałe.
B23: Regresja krokowa w tył
B26: y gdp lg | C26: X1Patent applications, nonresidents | D26: X2Population ages 05-09, female (% of female population) | E26: X3Survival to age 65 male | F26: X4domestic companies, t | G26: X5Imports of goods and services (% of GDP)=x2 | H26: X6Exports of goods and services (% of GDP) | I26: X7 Total reserves (includes gold, current US$) | J26: X8 x%Inflation, consumer prices (annual %) | K26: X9Population, total | L26: X10Population growth (annual %)
B27: 26.108963 | C27: 1.948 | D27: 39.02 | E27: 52.1 | F27: 1.151 | G27: 7.85 | H27: 5.84 | I27: 8.2157324e+09 | J27: 11.87 | K27: 745826546 | L27: 2.28
B28: 26.080598 | C28: 2.291 | D28: 38.91 | E28: 52.6 | F28: 1.295 | G28: 7.73 | H28: 6.28 | I28: 8.5359445e+09 | J28: 8.32 | K28: 762895156 | L28: 2.29
B29: 26.172207 | C29: 2.493 | D29: 38.75 | E29: 53.11 | F29: 1.529 | G29: 7.65 | H29: 5.25 | I29: 9.493103e+09 | J29: 5.56 | K29: 780242084 | L29: 2.27
B30: 26.240662 | C30: 2.497 | D30: 38.71 | E30: 53.62 | F30: 1.911 | G30: 7.02 | H30: 5.2 | I30: 1.0480103e+10 | J30: 8.73 | K30: 797878993 | L30: 2.26
B31: 26.354598 | C31: 2.52 | D31: 38.58 | E31: 54.12 | F31: 2.095 | G31: 6.98 | H31: 5.6 | I31: 1.1511741e+10 | J31: 8.8 | K31: 815716125 | L31: 2.24
B32: 26.415613 | C32: 2.504 | D32: 38.4 | E32: 55.02 | F32: 2.24 | G32: 7.46 | H32: 6.04 | I32: 9.1858394e+09 | J32: 9.38 | K32: 833729681 | L32: 2.21
B33: 26.413768 | C33: 2.6 | D33: 38.19 | E33: 55.91 | F33: 2.407 | G33: 8.15 | H33: 7.02 | I33: 8.0484559e+09 | J33: 7.07 | K33: 852012673 | L33: 2.19
B34: 26.494642 | C34: 2.673 | D34: 37.97 | E34: 56.8 | F34: 2.435 | G34: 8.45 | H34: 7.05 | I34: 5.6374464e+09 | J34: 8.97 | K34: 870452165 | L34: 2.16
B35: 26.322078 | C35: 2.328 | D35: 37.77 | E35: 57.7 | F35: 2.556 | G35: 8.49 | H35: 8.49 | I35: 7.6159875e+09 | J35: 13.87 | K35: 888941756 | L35: 2.12
B36: 26.38695 | C36: 2.176 | D36: 37.54 | E36: 58.59 | F36: 2.781 | G36: 9.59 | H36: 8.84 | I36: 9.538786e+09 | J36: 11.79 | K36: 907574049 | L36: 2.1
B37: 26.355538 | C37: 2.511 | D37: 37.29 | E37: 59.44 | F37: 3.263 | G37: 9.82 | H37: 9.83 | I37: 1.4674627e+10 | J37: 6.33 | K37: 926351297 | L37: 2.07
B38: 26.514068 | C38: 3.212 | D38: 36.99 | E38: 60.3 | F38: 4.413 | G38: 10.19 | H38: 9.89 | I38: 2.4220928e+10 | J38: 10.25 | K38: 945261958 | L38: 2.04
... B43: 26.851925 | C43: 2.62 | D43: 35.16 | E43: 64.05 | F43: 5.789 | G43: 13.36 | H43: 11.45 | I43: 3.6005296e+10 | J43: 4.67 | K43: 1040500054 | L43: 1.87
B44: 26.872578 | C44: 6.332 | D44: 34.73 | E44: 64.65 | F44: 5.853 | G44: 13.9 | H44: 13 | I44: 4.1059062e+10 | J44: 4.01 | K44: 1059633675 | L44: 1.84 | T44: PODSUMOWANIE - WYJŚCIE
B45: 26.908324 | C45: 8.213 | D45: 34.36 | E45: 65.25 | F45: 5.795 | G45: 13.43 | H45: 12.56 | I45: 4.9050841e+10 | J45: 3.78 | K45: 1078970907 | L45: 1.82
B46: 26.967312 | C46: 8.772 | D46: 33.97 | E46: 65.85 | F46: 5.65 | G46: 15.24 | H46: 14.26 | I46: 7.1607865e+10 | J46: 4.3 | K46: 1098313039 | L46: 1.79 | T46: Statystyki regresji
B47: 27.132946 | C47: 9.188 | D47: 33.56 | E47: 66.42 | F47: 5.644 | G47: 15.64 | H47: 14.95 | I47: 1.0373721e+11 | J47: 3.81 | K47: 1117415123 | L47: 1.74 | T47: Wielokrotność R | U47: 0.99822095
B48: 27.287331 | C48: 13.452 | D48: 33.15 | E48: 66.99 | F48: 4.725 | G48: 19.64 | H48: 17.86 | I48: 1.3163114e+11 | J48: 3.77 | K48: 1136264583 | L48: 1.69 | T48: R kwadrat | U48: 0.99644507
B49: 27.433035 | C49: 19.661 | D49: 32.74 | E49: 67.56 | F49: 4.763 | G49: 22.4 | H49: 19.61 | I49: 1.3782483e+11 | J49: 4.25 | K49: 1154638713 | L49: 1.62 | T49: Dopasowany R kwadrat | U49: 0.99512843
B50: 27.569422 | C50: 23.242 | D50: 32.38 | E50: 68.14 | F50: 4.796 | G50: 24.46 | H50: 21.27 | I50: 1.7804979e+11 | J50: 5.8 | K50: 1172373788 | L50: 1.54 | T50: Błąd standardowy | U50: 0.061561858
B51: 27.827193 | C51: 28.922 | D51: 32.01 | E51: 68.71 | F51: 4.887 | G51: 24.89 | H51: 20.8 | I51: 2.765781e+11 | J51: 6.37 | K51: 1189691809 | L51: 1.48 | T51: Obserwacje | U51: 38
B52: 27.812422 | C52: 30.387 | D52: 31.64 | E52: 69.41 | F52: 4.921 | G52: 29.27 | H52: 24.1 | I52: 2.5742273e+11 | J52: 8.35 | K52: 1206734806 | L52: 1.43
B53: 27.925098 | C53: 27.025 | D53: 31.24 | E53: 70.11 | F53: 4.955 | G53: 25.87 | H53: 20.4 | I53: 2.8468289e+11 | J53: 10.88 | K53: 1223640160 | L53: 1.4 | T53: ANALIZA WARIANCJI
B54: 28.147202 | C54: 30.909 | D54: 30.81 | E54: 70.8 | F54: 5.034 | G54: 26.85 | H54: 22.4 | I54: 3.0048017e+11 | J54: 11.99 | K54: 1240613620 | L54: 1.39 | U54: df | V54: SS | W54: MS | X54: F | Y54: Istotność F
B55: 28.231532 | C55: 33.45 | D55: 30.4 | E55: 71.5 | F55: 5.112 | G55: 31.08 | H55: 24.54 | I55: 2.9873946e+11 | J55: 8.91 | K55: 1257621191 | L55: 1.37 | T55: Regresja | U55: 10 | V55: 28.682014 | W55: 2.8682014 | X55: 756.80886 | Y55: 2.3039274e-30
B56: 28.234045 | C56: 34.402 | D56: 29.93 | E56: 72.2 | F56: 5.191 | G56: 31.26 | H56: 24.53 | I56: 3.0042552e+11 | J56: 9.48 | K56: 1274487215 | L56: 1.34 | T56: Resztkowy | U56: 27 | V56: 0.10232628 | W56: 0.0037898624
...

Sheet 3a. Obserwacje nietypowe
A1: Wykrywanie obserwacji nietypowych
A4: Należy w analizie uwzględnić:
A6: identyfikację obserwacji odstających
A7: identyfikację obserwacji dźwigniowych
A8: identyfikację obserwacji wpływowych
A11: Jeśli usuną Państwo jakąś obserwację, to warto ponownie przeprowadzić dobór zmiennych.
C14: brak obserwacji wplywowych , 2 obserwacje dzwigniowe ale nie wplywowe
B75: Obs nietypowe
B210: Brak obserwacji nietypowych
D213: Wnioski: brak obserwacji wpływowych , 2 obserwacje dźwigniowe ale nie wpływowe.

Sheet 3b. Współliniowość
A1: Badanie współliniowości
A7: Należy w analizie wykorzystać czynnik inflacji wariancji:
G10: VIF* = 10
A12: VIFk - czynnik inflacji wariancji
A13: R2 - współczynnik determinacji (dla oszacowanego modelu pomocniczego, w którym jedna ze zmiennych objaśniających jest zmienną objaśnianą)
H18: dla modelu zm objasniana x1 a zm obajsniajace x2 x5 x6
A24: H0 | B24: Brak wspolliniowsci modelu
A25: H1 | B25: Wystepuje wspolliniowsc modelu
A26: VIFk>10 | B26: Odrzucamy H0 występuje współliniowść modelu
A27: Wystepuje inflacja która zakłóca model
A28: VIFk | B28: =1/(1-0.964135) -> 27.882337
B29: W wyniku testu wyszlo ze wystepuje wspolliniowsc modelu zm objasniajace sa skorelowane co wplywa na jakosc i wiarygodnosc wynikow . Estymatory kmnk sa nieobciazone ale maja duza wariancje ich wartosci mogą odbiegac od wartosci prawdziwych w malych probach trudno jednoznacznie okreslic wplyw poszczegolnych zmiennych na zm objasniana.
B33: W zwiazku z wspoliniowoscia nalezaloby polaczyc silnie skorelowane zmienne

Sheet 4. Istotność parametrów
A1: W tym arkuszu należy zamieścić wyniki weryfikacji istotności parametrów strukturalnych modelu
A3: W szczególności, proszę tu napisać:
A4: Jakie hipotezy są weryfikowane?
A5: Jaka jest metoda weryfikacji tych hipotez?
A6: Jakie są wnioski dotyczące istotności parametrów strukturalnych?
A21: H0 Bi=0
A22: H1 Bi!=0 | G22: Metoda weryfikacji istotnosci testem t studenta
A23: We wszytkich odrzucamy H0 , parametry sa istotne
B29: Metoda weryfikacji istotnosci testem t studenta

Sheet 5. Dopasowanie modelu do danych
A1: W tym arkuszu należy zamieścić wyniki dotyczące zgodności modelu z danymi empirycznymi
A3: W szczególności, proszę zinterpretować:
A4: odchylenie standardowe reszt (standardowy błąd estymacji modelu)
A5: współczynnik determinacji
A6: współczynnik korelacji wielorakiej
A10: wsp korelacji wielorakiej | B10: =SQRT(0.994303) -> 0.99714743
A11: Jak silnie wszystkie zm objasniajace wplywaja razem na zm. Objasniana - wystepuje bardzo silnie korelacja dodatnia wzrost jednej zm wiaze się z znacznym wzorstem zm. Objasnianej
A13: odch standreszt | B13: =SQRT(0.004969) -> 0.070491134
A14: Wartosci obserwowane roznia się srednio o 0,07049 od wartosci wyliczonych przez model
A16: wsp determinacji | B16: =0.994303 -> 0.994303
A17: 99% zm zostało wyjasnione przez model
A37: Współczynnik korelacji wielorakiej | B37: 0.99714743
A38: Jak silnie wszystkie zmienne objaśniające wpływają razem na zmienna objaśniana - występuje bardzo silnie korelacja dodatnia. Bardzo wysoki związek liniowy między zmienną zależną a zmiennymi niezależnymi. Model regresji jest w stanie dosyć dokładnie przewidywać wartości zmiennej zależnej.
A40: odchylenie standardowy reszt | B40: 0.070491134
A41: Wartości obserwowane różnią się średnio o 0,07049 od wartości wyliczonych przez model.
A43: współczynnik determinacji | B43: 0.994303
A44: 99% zmienności zmiennej objaśnianej zostało wyjaśnione przez model.

Sheet 6. Badanie losowości
A1: Badanie losowości składnika epsylon
A3: W szczególności, proszę tu napisać:
A4: Jaka hipoteza jest weryfikowana?
A5: Jaka jest metoda weryfikacji tej hipotezy? | P5: reszty
A6: Jakie są wnioski uzyskane na podstawie zastosowanego testu? | P6: -0.099833713 | Q6: =IF(P6>0, 1,0) -> 0
P7: -0.13316087 | Q7: =IF(P7>0, 1,0) -> 0
P8: -0.10291788 | Q8: =IF(P8>0, 1,0) -> 0
P9: -0.023704522 | Q9: =IF(P9>0, 1,0) -> 0 | R9: 1
P10: 0.084695896 | Q10: =IF(P10>0, 1,0) -> 1
F11: H0 : y1=b0+b1*x1+b2*x2+b3*x3+b4*x4 | P11: 0.1192043 | Q11: =IF(P11>0, 1,0) -> 1
F12: H1: y1!=b0+b1*x1+b2*x2+b3*x3+b4*x4 | P12: 0.0963084 | Q12: =IF(P12>0, 1,0) -> 1
F13: Wykorzystujemy test serii | P13: 0.13411158 | Q13: =IF(P13>0, 1,0) -> 1 | R13: 2
P14: -0.014352397 | Q14: =IF(P14>0, 1,0) -> 0
P15: -0.0024814984 | Q15: =IF(P15>0, 1,0) -> 0
G16: S= | H16: 17 | P16: -0.051757914 | Q16: =IF(P16>0, 1,0) -> 0 | R16: 3
G17: n2 | H17: =COUNTIF(Q6:Q43,"0") -> 21 | I17: -ujemne | P17: 0.038126925 | Q17: =IF(P17>0, 1,0) -> 1
G18: n1 | H18: =COUNTIF(Q6:Q43, 1) -> 17 | I18: -dodatnie | P18: 0.024963508 | Q18: =IF(P18>0, 1,0) -> 1
P19: 0.024687401 | Q19: =IF(P19>0, 1,0) -> 1 | R19: 4
G20: s1 | P20: -0.00095650807 | Q20: =IF(P20>0, 1,0) -> 0
P21: -0.030548043 | Q21: =IF(P21>0, 1,0) -> 0 | R21: 5
G22: ES | H22: =(2*H18*H17/(H18+H17))+1 -> 19.789474 | P22: 0.06592269 | Q22: =IF(P22>0, 1,0) -> 1 | R22: 6
G23: sigma s | H23: =SQRT((2*H18*H17*(2*H18*H17-H18-H17))/((H18+H17)^2*(H18+H17-1))) -> 3.0056472 | P23: -0.014799479 | Q23: =IF(P23>0, 1,0) -> 0
G24: Z | H24: =(H16-H22)/H23 -> -0.92807756 | P24: -0.073640339 | Q24: =IF(P24>0, 1,0) -> 0
G25: t* | H25: =2 -> 2 | P25: -0.080953303 | Q25: =IF(P25>0, 1,0) -> 0 | R25: 7
G26: |z| | H26: <t* | P26: 0.025367362 | Q26: =IF(P26>0, 1,0) -> 1
G27: Brak podstaw do odrzucenia h0 | P27: 0.014580297 | Q27: =IF(P27>0, 1,0) -> 1 | R27: 8
F28: Postac modelu została dobrana poprawnie | P28: -0.04571102 | Q28: =IF(P28>0, 1,0) -> 0
F29: Reszty sa losowe skladnik losowy zachowuje się zgodnie z zalozeniami kmnk model nie jest blednie wyspecyfikowany , reszty maja charakter los | P29: -0.038722724 | Q29: =IF(P29>0, 1,0) -> 0 | R29: 9
P30: 0.022671102 | Q30: =IF(P30>0, 1,0) -> 1 | R30: 10
P31: -0.094489347 | Q31: =IF(P31>0, 1,0) -> 0
P32: -0.0034030544 | Q32: =IF(P32>0, 1,0) -> 0 | R32: 11
P33: 0.11631587 | Q33: =IF(P33>0, 1,0) -> 1
P34: 0.035901935 | Q34: =IF(P34>0, 1,0) -> 1 | R34: 12
P35: -0.057981038 | Q35: =IF(P35>0, 1,0) -> 0 | R35: 13
P36: 0.036148142 | Q36: =IF(P36>0, 1,0) -> 1
P37: 0.072088445 | Q37: =IF(P37>0, 1,0) -> 1 | R37: 14
P38: -0.010376672 | Q38: =IF(P38>0, 1,0) -> 0 | R38: 15
P39: 0.035194899 | Q39: =IF(P39>0, 1,0) -> 1
P40: 0.071991571 | Q40: =IF(P40>0, 1,0) -> 1 | R40: 16
P41: -0.029233133 | Q41: =IF(P41>0, 1,0) -> 0
...

Sheet 7. Badanie normalności
A1: Testy weryfikujące normalność rozkładu składnika losowego
A3: W szczególności, proszę tu napisać:
A4: Jaka hipoteza jest weryfikowana?
A5: Jaka jest metoda weryfikacji tej hipotezy?
A6: Jakie są wnioski uzyskane na podstawie zastosowanego testu?
J7: reszty
A8: Uwaga: | B8: H0 skladnik los ma rozklad norm | J8: -0.099833713 | K8: =J8^2 -> 0.0099667702 | L8: =J8^3 -> -0.00099501967 | M8: =J8^4 -> 9.9336508e-05
A9: test Shapiro-Wilka, dla n z zakresu [4; 2000] | B9: H1 skladnik los nie ma rozklad norm | J9: -0.13316087 | K9: =J9^2 -> 0.017731818 | L9: =J9^3 -> -0.0023611844 | M9: =J9^4 -> 0.00031441737
A10: test Jarque'a-Bera dla bardzo dużych n | B10: Test Jarque Berry | J10: -0.10291788 | K10: =J10^2 -> 0.01059209 | L10: =J10^3 -> -0.0010901155 | M10: =J10^4 -> 0.00011219238
J11: -0.023704522 | K11: =J11^2 -> 0.00056190434 | L11: =J11^3 -> -1.3319674e-05 | M11: =J11^4 -> 3.1573649e-07
J12: 0.084695896 | K12: =J12^2 -> 0.0071733948 | L12: =J12^3 -> 0.00060755709 | M12: =J12^4 -> 5.1457592e-05
A13: Uwaga: | B13: A | C13: =C15/C17^3 -> 0.10374892 | J13: 0.1192043 | K13: =J13^2 -> 0.014209665 | L13: =J13^3 -> 0.0016938531 | M13: =J13^4 -> 0.00020191457
A14: W Gretlu domyślnie jest wykonywany test Doornika-Hansena. Aby wykonać test Shapiro-Wilka, reszty trzeba wcześniej zapisać. Następnie, najechać na tę zmienną w menu głównym i wybrać opcję Zmienna → testy normalności rozkładu. | B14: K | C14: =C16/C17^4 -> 2.3713988 | J14: 0.0963084 | K14: =J14^2 -> 0.0092753079 | L14: =J14^3 -> 0.00089329007 | M14: =J14^4 -> 8.6031337e-05
B15: M3 | C15: =1/38*L46 -> 2.9408444e-05 | J15: 0.13411158 | K15: =J15^2 -> 0.017985916 | L15: =J15^3 -> 0.0024121196 | M15: =J15^4 -> 0.00032349316
B16: M4 | C16: =1/38*M46 -> 4.4155947e-05 | J16: -0.014352397 | K16: =J16^2 -> 0.00020599131 | L16: =J16^3 -> -2.9564691e-06 | M16: =J16^4 -> 4.243242e-08
A17: Można także wykonać polecenie skryptowe 'normtest nazwareszt --dhansen' lub --swilk lub --jbera. Np. aby uzyskać wynik testu Shapiro-Wilka należy w menu głównym wybrać opcję Plik > Plik poleceń skryptowych > nowy plik skryptowy > skrypt gretla: normtest nazwareszt | B17: S | C17: =SQRT(1/38*K46) -> 0.06568953 | J17: -0.0024814984 | K17: =J17^2 -> 6.1578343e-06 | L17: =J17^3 -> -1.5280656e-08 | M17: =J17^4 -> 3.7918923e-11
A18: --swilk | B18: n=38 | J18: -0.051757914 | K18: =J18^2 -> 0.0026788817 | L18: =J18^3 -> -0.00013865333 | M18: =J18^4 -> 7.176407e-06
A19: Uwaga: reszty trzeba wcześniej zapisać. | J19: 0.038126925 | K19: =J19^2 -> 0.0014536624 | L19: =J19^3 -> 5.5423679e-05 | M19: =J19^4 -> 2.1131345e-06
B20: JB | C20: =38/6*(C13^2+1/4*(C14-3)^2) -> 0.69380854 | J20: 0.024963508 | K20: =J20^2 -> 0.00062317673 | L20: =J20^3 -> 1.5556677e-05 | M20: =J20^4 -> 3.8834924e-07
J21: 0.024687401 | K21: =J21^2 -> 0.00060946775 | L21: =J21^3 -> 1.5046175e-05 | M21: =J21^4 -> 3.7145094e-07
B22: CHI^2* | C22: =_xlfn.CHISQ.INV.RT(0.05,2) -> 5.9914645 | J22: -0.00095650807 | K22: =J22^2 -> 9.1490769e-07 | L22: =J22^3 -> -8.7511659e-10 | M22: =J22^4 -> 8.3705609e-13
J23: -0.030548043 | K23: =J23^2 -> 0.0009331829 | L23: =J23^3 -> -2.8506911e-05 | M23: =J23^4 -> 8.7083033e-07
B24: JB<CHI^2* | J24: 0.06592269 | K24: =J24^2 -> 0.004345801 | L24: =J24^3 -> 0.00028648689 | M24: =J24^4 -> 1.8885986e-05
B25: brak podstaw do odrzucenia h0 skladnik losowy ma rozkład normalny | J25: -0.014799479 | K25: =J25^2 -> 0.00021902459 | L25: =J25^3 -> -3.24145e-06 | M25: =J25^4 -> 4.7971772e-08
B26: Wniosek: reszty modelu maja rozklad normalny , jest spelnione zalozenie kmnk reszty sa losowe i nie wykazuja systematycznych wzorcow co sugeruje ze model jest dobrze dopasowany | J26: -0.073640339 | K26: =J26^2 -> 0.0054228995 | L26: =J26^3 -> -0.00039934416 | M26: =J26^4 -> 2.9407839e-05
J27: -0.080953303 | K27: =J27^2 -> 0.0065534373 | L27: =J27^3 -> -0.00053052239 | M27: =J27^4 -> 4.294754e-05
J28: 0.025367362 | K28: =J28^2 -> 0.00064350307 | L28: =J28^3 -> 1.6323976e-05 | M28: =J28^4 -> 4.140962e-07
J29: 0.014580297 | K29: =J29^2 -> 0.00021258507 | L29: =J29^3 -> 3.0995535e-06 | M29: =J29^4 -> 4.5192411e-08
J30: -0.04571102 | K30: =J30^2 -> 0.0020894974 | L30: =J30^3 -> -9.5513056e-05 | M30: =J30^4 -> 4.3659992e-06
J31: -0.038722724 | K31: =J31^2 -> 0.0014994494 | L31: =J31^3 -> -5.8062764e-05 | M31: =J31^4 -> 2.2483484e-06
J32: 0.022671102 | K32: =J32^2 -> 0.00051397889 | L32: =J32^3 -> 1.1652468e-05 | M32: =J32^4 -> 2.641743e-07
J33: -0.094489347 | K33: =J33^2 -> 0.0089282366 | L33: =J33^3 -> -0.00084362325 | M33: =J33^4 -> 7.9713409e-05
J34: -0.0034030544 | K34: =J34^2 -> 1.1580779e-05 | L34: =J34^3 -> -3.9410021e-08 | M34: =J34^4 -> 1.3411444e-10
J35: 0.11631587 | K35: =J35^2 -> 0.013529382 | L35: =J35^3 -> 0.0015736819 | M35: =J35^4 -> 0.00018304418
J36: 0.035901935 | K36: =J36^2 -> 0.001288949 | L36: =J36^3 -> 4.6275763e-05 | M36: =J36^4 -> 1.6613894e-06
J37: -0.057981038 | K37: =J37^2 -> 0.0033618008 | L37: =J37^3 -> -0.0001949207 | M37: =J37^4 -> 1.1301705e-05
J38: 0.036148142 | K38: =J38^2 -> 0.0013066882 | L38: =J38^3 -> 4.723435e-05 | M38: =J38^4 -> 1.707434e-06
... J45: -0.08192528 | K45: =J45^2 -> 0.0067117514 | L45: =J45^3 -> -0.00054986211 | M45: =J45^4 -> 4.5047607e-05
I46: suma | J46: =SUM(J8:J45) -> -1.9895197e-13 | K46: =SUM(K8:K45) -> 0.16397434 | L46: =SUM(L8:L45) -> 0.0011175209 | M46: =SUM(M8:M45) -> 0.001677926

Sheet 8. Badanie braku autokorelacji 
A1: Autokorelację należy zbadać dla szeregów czasowych
A3: W sytuacji, gdy analizują Państwo dane przekrojowe, w celu sprawdzenia Państwa wiedzy, proszę także wykonać w tym opracowaniu badanie autokorelacji.
A4: Wcześniej jednak proszę posortować dane, np. wg jednej ze zmiennych objaśniających
A6: W szczególności, proszę tu napisać:
A7: Jaka hipoteza jest weryfikowana?
A8: Jaka jest metoda weryfikacji tej hipotezy?
A9: Jakie są wnioski uzyskane na podstawie zastosowanego testu?
A12: Testy weryfikujące autokorelację składnika losowego
A13: test Durbina-Watsona
A14: test Breuscha-Godfreya - dla dużych prób
A16: H0 Brak autokorelacji
A17: H1 wystepuje autokorelacja
... A50: y^ = 32,34+0,0179x1-0,158x2+0,033x5-0,040x6

Sheet 9. Badanie homoskedastyczności
A1: Testy weryfikujące homoskedastyczność rozkładu składnika losowego
A3: W szczególności, proszę tu napisać:
A4: Jaka hipoteza jest weryfikowana?
A5: Jaka jest metoda weryfikacji tej hipotezy?
A6: Jakie są wnioski uzyskane na podstawie zastosowanego testu?
A8: Testy weryfikujące homoskedastyczności składnika losowego
A9: test Goldfelda-Quandta
A10: test White'a i Harveya-Godfreya - dla dużych prób | G10: Test Goldfend-quandta
A13: TEST WHITE
J16: 1 podpróba | S16: 2 podpróba
H19: 26.108963 | I19: 1.948 | J19: 39.02 | K19: 7.85 | L19: 5.84 | Q19: 27.287331 | R19: 13.452 | S19: 33.15 | T19: 19.64 | U19: 17.86
H20: 26.080598 | I20: 2.291 | J20: 38.91 | K20: 7.73 | L20: 6.28 | Q20: 27.433035 | R20: 19.661 | S20: 32.74 | T20: 22.4 | U20: 19.61
H21: 26.172207 | I21: 2.493 | J21: 38.75 | K21: 7.65 | L21: 5.25 | Q21: 27.569422 | R21: 23.242 | S21: 32.38 | T21: 24.46 | U21: 21.27
H22: 26.240662 | I22: 2.497 | J22: 38.71 | K22: 7.02 | L22: 5.2 | Q22: 27.827193 | R22: 28.922 | S22: 32.01 | T22: 24.89 | U22: 20.8
H23: 26.354598 | I23: 2.52 | J23: 38.58 | K23: 6.98 | L23: 5.6 | Q23: 27.812422 | R23: 30.387 | S23: 31.64 | T23: 29.27 | U23: 24.1
H24: 26.415613 | I24: 2.504 | J24: 38.4 | K24: 7.46 | L24: 6.04 | Q24: 27.925098 | R24: 27.025 | S24: 31.24 | T24: 25.87 | U24: 20.4
H25: 26.413768 | I25: 2.6 | J25: 38.19 | K25: 8.15 | L25: 7.02 | Q25: 28.147202 | R25: 30.909 | S25: 30.81 | T25: 26.85 | U25: 22.4
H26: 26.494642 | I26: 2.673 | J26: 37.97 | K26: 8.45 | L26: 7.05 | Q26: 28.231532 | R26: 33.45 | S26: 30.4 | T26: 31.08 | U26: 24.54
H27: 26.322078 | I27: 2.328 | J27: 37.77 | K27: 8.49 | L27: 8.49 | Q27: 28.234045 | R27: 34.402 | S27: 29.93 | T27: 31.26 | U27: 24.53
H28: 26.38695 | I28: 2.176 | J28: 37.54 | K28: 9.59 | L28: 8.84 | Q28: 28.249834 | R28: 32.362 | S28: 29.43 | T28: 28.41 | U28: 25.43
H29: 26.355538 | I29: 2.511 | J29: 37.29 | K29: 9.82 | L29: 9.83 | Q29: 28.343543 | R29: 30.814 | S29: 28.93 | T29: 25.95 | U29: 22.97
H30: 26.514068 | I30: 3.212 | J30: 36.99 | K30: 10.19 | L30: 9.89 | Q30: 28.374665 | R30: 33.079 | S30: 28.44 | T30: 22.11 | U30: 19.81
... H35: 26.851925 | I35: 2.62 | J35: 35.16 | K35: 13.36 | L35: 11.45 | Q35: 28.612233 | R35: 33.63 | S35: 26.16 | T35: 19.1 | U35: 18.71
A42: H0 wystepuje homoskedastycznosc | I42: MS resztkowy= | J42: 0.005291098 | Q42: MS resztkowy= | R42: 0.004366021
A43: H1 wystepuje heteroskedastycznosc
A44: p value >0,05
A45: przyjmujemy H0 wystepuje homoskedastycznosc
A46: Wniosek W modelu wystepuje homoskedastycznosc wiec wszystkie wariancje skladnikow los sa stale dla wszystkich obserwacji niezaleznie od wartosci zm. Objasniajacych. Jedno z kluczowych zalozen kmnk zostalo spelnione estymatory kmnk sa efektywne czyli maja najmniejsza mozliwa wariancje sa liniowe nieobciazone i zgodne.
J47: F= | K47: =J42^2/R42^2 -> 1.4686556
J50: n1 | K50: =17-4-1 -> 12
J51: n2 | K51: =17-4-1 -> 12
J54: F* | K54: =_xlfn.F.INV.RT(0.05,K50,K51) -> 2.6866371
J57: =K47 -> 1.4686556 | K57: < | L57: =K54 -> 2.6866371
I61: odp: Brak podstaw do odrzucenia h0, o homoskedastyczności

Sheet 10. WNIOSKI
A1: Ogólny komentarz dotyczący modelu
A4: W szczególności:
A6: czy model spełnia nałożone na niego założenia?
A7: czy jest dobrze dopasowany do danych, itp.?
A8: jaka jest nterpretacja merytoryczna oszacowanych parametrów?
A9: czy proces modelowania zakończyl się sukcesem czy porażką?
A12: Uwaga: nisko będą punktowane opracowania zawierające interpretację typu:
A13: "jak X1 wzrasta o 1 to Y o wzrasta 0,7, ceteris paribus".
A14: Uwaga: ważne jest sprawdzenie, czy znaki oszacowań parametrów przy zmiennych są odpowiednie,
A15: to znaczy czy mają sens ekonomiczny i zdroworozsadkowy. | M15: y gdp lg | N15: X1Patent applications, nonresidents | O15: X2Population ages 05-09, female (% of female population) | P15: X5Imports of goods and services (% of GDP)=x2 | Q15: X6Exports of goods and services (% of GDP)
M18: y^ = 32,12 + 0,0194x1-0,153x2 + 0,029x5-0,034x6 | R18: model kmnk
M19: y^ = 32,34+0,0179x1-0,158x2+0,033x5-0,040x6 | R19: model umnk
A20: 1. | J20: 3.
A21: Na podstawie przeprowadzonych testów można sformułować następujące wnioski: Test normalności - nie odrzucono hipotezy o normalnym rozkładzie składnika losowego co oznacza ze składnik losowy ma rozkład zbliżony do normalnego. Test homoskedastyczność - Brak podstaw do odrzucenia H0 o stałej wariancji reszt wiec wariancja reszt jest stała co spełnia założenie kmnk. Test serii - nie odrzucono H0 o losowości składnik losowego epsylon co oznacza ze składnik ma charakter przypadkowy a model został poprawnie wyspecyfikowany. Współliniowość - stwierdzono występowanie współliniowości miedzy zmiennymi objaśniającymi. Powoduje to wzrost wariancji estymatorów , niestabilności współczynników i utrudnia jednoznaczna interpretacje wpływu poszczególnych zmiennych. Autokorelacja reszt- wykryto autokorelacje reszt co oznacza ze składnik losowy nie jest w pełni niezależny. Narusza jedno z podstawowych założeń kmnk i może prowadzić do błędnych wniosków z testów istotności w związku z tym przeprowadziliśmy umnk aby zapobiec autokorelacji reszt. | K21: Ze względu na wspolliniowsc interpretacja posczegolnych parametrow może być niedokonca poprawna y^=32,12+0,0194x1-0,153x2+0,029x5-0,034x6 1.Wyraz wolny - 32,12 - oznaczna przewidywana wartosc PKB gdy wszystkie zm objasniajace sa rowne 0 . Ekonomicznie: punkt startowy pkb gdy nie ma wartosc wszystkich zm objasniajacych jest rowna 0 w praktyce jest to bardziej wartosc teoretyczna niz realistyczna. 2.B1=0,0194 (wnioski o patenty) kazdy dodatkowy patenty zwieksza pkb o 0,0194 jednostki przy zalozeniu stalosci pozostalych parametrow . Ekonomicznie : wieksza liczba patentow powoduje wieksza innowacyjnosc oraz wzrost produktywnosci co powoduje wzrost pkb. Wartosc dodatnia jest zgodna z intuicja ekonomiczna. 3.Parametr B2=-0,153 wzrost x2 o jedna jednostke powoduje spadek PKB o 0,153jednostek przy zalozeniu stalosci reszty parametrow. Ekonomiczny: Ujemny wspolczynnik wymaga ostroznosci przy interpretacji moze to byc efekt statystyczny wynikajacy z korelacji z innymi zmiennymi a nie rzeczywisty efekt ekonomiczny . 4.B3 = 0,029 (import krajowy) wzrost udzialu importu o 1 % zwieksza pkb o 0,029 jednostki przy zalozeniu ze reszta zm jest stala. Ekonomicznie : wiekszy import moze swiadczyc o wiekszym wzroscie aktywnosci gospodarczej lepszych mozliwosciach produkcyjnych i konsumpcyjnych co pozytywnie wplywa na pkb. 5. B4=-0,034 (export krajowy) Wzrost udzialu o 1 % zmniejsza pkb o 0,034 jednostki przy zalozeniu ze reszta zm modelu jest stala . Ekonomicznie: Ujemny znak jest nietypowy bo zwykle wiekszy export wspiera pkb moze to byc efekt wspolliniowsci miedzy imortem a exportem wiec nalezy interpretowac ostroznie. Przykladowy scenariusz ekonomiczny : koszty produkcji exportowej przewyzszaja korzysci w krotkim okresie
A38: 2.
A39: R^2 = 0,99 oznacza ze model wyjasnia 99% zm zaleznej formalnie dopasowanie jest bardzo wysokie
K40: 4. | L40: Ocena końcowa - Podsumowując : model spełnia część kluczowych załóżeń (normalnosc , skedastycznosc , losowsc reszt) , ale narusza brak wspolliniowsci i autokorelacji co oznacza ze estymaotry kmnk nie sa efektywne proces estymacji nie zakonczyl się pelnym sukcesem model formalnie dopasowuje sie dobrze do danych ale z punktu widzenia wiarygodnosci interpretacyjnej i statytycznej nie mozna go uznac za wpelni poprawny, w zwiazku z autokorelacja i wspolliniowscia przeprowadzilismy proces estymacji umnk ktory jest odporny na autokorelacje i wspolliniowsc .Dzieki umnk estymatory pozostana nieobciazone i efektywne nawet przy naruszeniu tych zalozen . Wnioski do modelu umnk . Estymatory sa nieobciazone i efektywne w przeciwienstwie do kmnk w obecnosci autokorelacji estymatory maja min wariancje posrod liniowych estymatorow nieobciazonych. Dzieki temu wspolczynniki regresji mozna interpretowac wiarygodnie.
